Workbook
Name ALL_BRANCH_CODES: LK_DropdownLists!$FB$2:$FB$21
Name ALL_BRANCH_NAMES: LK_DropdownLists!$FA$2:$FA$21
Name ALL_BRANCH_SWIFTS: LK_DropdownLists!$FC$2:$FC$21
Name ALL_DEPT_KEYS: LK_DropdownLists!$V$2:$V$87
Name ALL_DEPT_NAMES: LK_DropdownLists!$U$2:$U$87
Name ALL_PROV_KEYS: LK_DropdownLists!$DJ$2:$DJ$36
Name ALL_PROV_NAMES: LK_DropdownLists!$DI$2:$DI$36
Name BANK_KEYS: LK_DropdownLists!$EU$2:$EU$6
Name BANK_LIST: LK_DropdownLists!$FL$2:$FL$29
Name BRANCH_ABL: LK_DropdownLists!$GA$2:$GA$4
Name BRANCH_ANZ: LK_DropdownLists!$GL$2:$GL$2
Name BRANCH_APB: LK_DropdownLists!$FO$2:$FO$8
Name BRANCH_BAY: LK_DropdownLists!$GI$2:$GI$2
Name BRANCH_BBL: LK_DropdownLists!$GH$2:$GH$2
Name BRANCH_BCEL: LK_DropdownLists!$FM$2:$FM$13
Name BRANCH_BFL: LK_DropdownLists!$FS$2:$FS$3
Name BRANCH_BIC: LK_DropdownLists!$FV$2:$FV$3
Name BRANCH_BOC: LK_DropdownLists!$GN$2:$GN$2
Name BRANCH_CAB: LK_DropdownLists!$GB$2:$GB$2
Name BRANCH_ICB: LK_DropdownLists!$FX$2:$FX$2
Name BRANCH_ICBC: LK_DropdownLists!$GM$2:$GM$2
Name BRANCH_JDB: LK_DropdownLists!$FQ$2:$FQ$6
Name BRANCH_KTB: LK_DropdownLists!$GJ$2:$GJ$2
Name BRANCH_LCNB: LK_DropdownLists!$FT$2:$FT$4
Name BRANCH_LDB: LK_DropdownLists!$FN$2:$FN$8
Name BRANCH_LMI: LK_DropdownLists!$FY$2:$FY$2
Name BRANCH_LVB: LK_DropdownLists!$FR$2:$FR$4
Name BRANCH_MJBL: LK_DropdownLists!$FZ$2:$FZ$3
Name BRANCH_NBB: LK_DropdownLists!$FP$2:$FP$4
Name BRANCH_PBL: LK_DropdownLists!$GC$2:$GC$2
Name BRANCH_PSV: LK_DropdownLists!$FU$2:$FU$7
Name BRANCH_SCBV: LK_DropdownLists!$GK$2:$GK$2
Name BRANCH_SCL: LK_DropdownLists!$GD$2:$GD$3
Name BRANCH_SHB: LK_DropdownLists!$GE$2:$GE$2
Name BRANCH_STB: LK_DropdownLists!$FW$2:$FW$3
Name BRANCH_VCB: LK_DropdownLists!$GF$2:$GF$2
Name BRANCH_VTB: LK_DropdownLists!$GG$2:$GG$2
Name COUNTRY_KEYS: LK_DropdownLists!$DF$2:$DF$3
Name COUNTRY_LIST: LK_DropdownLists!$DE$2:$DE$3
Name DEPT_CHAM: LK_DropdownLists!$Q$2:$Q$5
Name DEPT_KHAMM: LK_DropdownLists!$T$2:$T$5
Name DEPT_LUANGPB: LK_DropdownLists!$R$2:$R$5
Name DEPT_MFA: LK_DropdownLists!$H$2:$H$6
Name DEPT_MLSW: LK_DropdownLists!$J$2:$J$6
Name DEPT_MOAF: LK_DropdownLists!$I$2:$I$6
Name DEPT_MOES: LK_DropdownLists!$E$2:$E$7
Name DEPT_MOF: LK_DropdownLists!$C$2:$C$7
Name DEPT_MOH: LK_DropdownLists!$D$2:$D$7
Name DEPT_MOHA: LK_DropdownLists!$F$2:$F$6
Name DEPT_MOIC: LK_DropdownLists!$L$2:$L$5
Name DEPT_MOJ: LK_DropdownLists!$M$2:$M$5
Name DEPT_MONRE: LK_DropdownLists!$K$2:$K$5
Name DEPT_MPI: LK_DropdownLists!$N$2:$N$5
Name DEPT_MPWT: LK_DropdownLists!$G$2:$G$6
Name DEPT_NA: LK_DropdownLists!$O$2:$O$7
Name DEPT_SAVAN: LK_DropdownLists!$S$2:$S$5
Name DEPT_VTCAP: LK_DropdownLists!$P$2:$P$6
Name DIST_ATP: LK_DropdownLists!$EA$2:$EA$6
Name DIST_BKO: LK_DropdownLists!$DO$2:$DO$6
Name DIST_BLK: LK_DropdownLists!$DU$2:$DU$7

Sheet HOME
A2: LAO PDR GOVERNMENT PAYROLL INFORMATION TOOLKIT
A6: 📂 NAVIGATE TO SHEETS
A8: =HYPERLINK("#'HOME'!A1","🏠 Home") -> 🏠 Home | D8: =HYPERLINK("#'INSTRUCTIONS'!A1","📋 Instructions") -> 📋 Instructions | G8: =HYPERLINK("#'EMPLOYEE_MASTER'!A1","👤 Employee Master") -> 👤 Employee Master | J8: =HYPERLINK("#'PAYROLL_CALC'!A1","💵 Payroll Calc") -> 💵 Payroll Calc
A9: This navigation page | D9: What to update & workflow | G9: 500 records – main input sheet | J9: Monthly payroll output
A11: =HYPERLINK("#'LK_OrgMaster'!A1","🏛️ Org Master") -> 🏛️ Org Master | D11: =HYPERLINK("#'LK_LocationMaster'!A1","📍 Location Master") -> 📍 Location Master | G11: =HYPERLINK("#'LK_BankMaster'!A1","🏦 Bank Master") -> 🏦 Bank Master | J11: =HYPERLINK("#'LK_GradeDerivation'!A1","🎓 Grade Derivation") -> 🎓 Grade Derivation
A12: Ministry→Dept→Division hierarchy | D12: Country→Province→District | G12: Bank→Branch hierarchy | J12: Edu×Experience→Grade/Step
A14: =HYPERLINK("#'LK_GradeStep'!A1","📊 Grade/Step Rates") -> 📊 Grade/Step Rates | D14: =HYPERLINK("#'LK_AllowanceRates'!A1","💰 Allowance Rates") -> 💰 Allowance Rates | G14: =HYPERLINK("#'LK_PIT'!A1","🧮 PIT Brackets") -> 🧮 PIT Brackets
A15: Multiplier lookup table | D15: All rates – update here | G15: Income tax brackets
A25: ⚠️ DISCLAIMER: This toolkit contains mock data for illustration and stakeholder review. All names, IDs and figures are fictitious. Finance departments must verify all rates against current MoF circulars, SSO decrees, and GDT orders before operational use.
A29: ສາທາລະນະລັດ ປະຊາທິປະໄຕ ປະຊາຊົນລາວ | Lao People's Democratic Republic

Sheet INSTRUCTIONS
A1: 📋 INSTRUCTIONS — Lao PDR Government Payroll Toolkit
A2: Read this sheet fully before making any changes to the workbook. 🟡 Yellow cells = manual input. 🟢 Green cells = auto-calculated (do NOT edit). All master lookup tables drive downstream calculations automatically — change a master table and every dependent field across all 500 records updates instantly.
A3: 1. COLOUR CODING GUIDE
A4: Element / Field | B4: Description | C4: Frequency / Trigger
A5: 🟡 Yellow background (Blue text) | B5: Editable INPUT cell — enter or update data here. These are the only cells stakeholders should write into. | C5: As required
A6: 🟢 Green background (Green text) | B6: AUTO-CALCULATED formula cell — driven by master tables or other inputs. DO NOT edit. Editing will break the chain of calculations. | C6: Never edit
A7: ⬜ White background | B7: Reference or display value — informational, not used in formulas. | C7: Read only
A8: 🔴 Red / Orange text in master tables | B8: Flagged value requiring attention (e.g. Is Remote = Yes, Is Hazardous = Yes in Location Master). | C8: Informational
A9: 2. DEPENDENT DROPDOWNS — HOW THEY WORK
A10: ℹ️ 159 named ranges power all dropdowns. They are stored in the hidden LK_DropdownLists sheet. Each dropdown is driven by INDIRECT() — selecting a value in the parent column automatically narrows the child dropdown to only relevant options.
A11: Element / Field | B11: Description | C11: Frequency / Trigger
A12: Ministry (Col T) → Dept (Col U) → Division (Col V) | B12: Select Ministry first. Department dropdown immediately narrows to only that ministry's departments. Then select Department — Division narrows to only that department's divisions. Driven by named ranges DEPT_<MinistryKey> and DIV_<DeptKey> in LK_DropdownLists. | C12: Org Master driven
A13: Service Country (Col W) → Province (Col X) → District (Col Y) | B13: Select Country (Lao PDR or Foreign/International) first. Province dropdown narrows to only that country's provinces or postings. Then select Province — District narrows to that province's districts. Driven by PROV_<CountryKey> and DIST_<ProvinceKey> named ranges. | C13: Location Master driven
A14: Position (Col M) → driven by Profession (Col Z) | B14: Position dropdown shows only positions relevant to the employee's Profession Category. Profession (Col Z) is auto-derived from Ministry via LK_OrgMaster. Named ranges: POS_TEACHER, POS_MEDICAL, POS_FINANCE, POS_ADMINISTRATION, POS_TECHNICAL, POS_LEGAL, POS_DIPLOMATIC, POS_GENERAL. | C14: Org Master / Profession driven
A15: Bank Name (Col AJ) → Bank Branch (Col AK) | B15: Select Bank Name first. Branch dropdown narrows to only that bank's branches. Driven by BRANCH_<BankKey> named ranges (e.g. BRANCH_BCEL shows all 8 BCEL branches). Bank Master has 5 banks and 20 branches total. | C15: Bank Master driven
A16: Prior Experience (Col O) → Grade (Col P) → Step (Col Q) | B16: Prior Experience is the only manual grade input. Enter years worked before joining government. Grade and Step auto-derive via SUMPRODUCT against LK_GradeDerivation (Education × Exp band). If left blank, Grade defaults to the education baseline (0 prior exp row). | C16: Grade Derivation driven
A17: 3. MASTER LOOKUP TABLES — WHAT TO UPDATE & WHERE
A18: ⭐ RULE: Never change values in PAYROLL_CALC or EMPLOYEE_MASTER formula cells (green). All changes go into the master tables below. One update here flows to all 500 employee records automatically.
A19: Element / Field | B19: Description | C19: Frequency / Trigger
A20: LK_GradeStep ⭐ | B20: TWO INPUT COLUMNS: Col D = Multiplier | Col E = Index Value (LAK). Basic Salary = Index Value × Multiplier for each employee's grade/step. ► Update Col E (Index Value) when MoF issues a new ຄ່າດັດສະນີ circular — set the same LAK amount across all 100 rows for a uniform index, or enter different values per grade row if MoF ever introduces a tiered/grade-differentiated index. ► Update Col D (Multiplier) when Civil Service Authority revises the multiplier table. | C20: Per MoF circular (Index Value) / Per CSA order (Multiplier)
A21: LK_GradeDerivation ⭐ | B21: Maps Education Level × Prior Experience band → Grade & Step. 126 rows (6 education levels × 21 experience bands). ► Update Col D (Grade) and Col E (Step) if CSA revises entry grade rules. ► Do NOT change Col A (Education) or Cols B/C (Exp Min/Max) unless adding new bands — these are the lookup keys used by Employee Master SUMPRODUCT formulas. | C21: Per CSA revision
A22: LK_OrgMaster ⭐ | B22: Full Ministry → Department → Division hierarchy (18 orgs, 86 dept rows). Three derived fields in Employee Master source from here: (1) Profession Category (Col F) → drives Position dropdown and Teaching/Medical allowances. (2) NA Allowance Eligible (Col G) → drives Is NA Member and NA Member Allowance. (3) Field Allowance Type (Col H) → Teaching = Teaching Allowance, Medical = Medical Allowance. ► Add new ministries/departments as new rows. ► Change profession/allowance type in Cols F-H as needed. DO NOT change Ministry Key (Col C) or Dept Key (Col E) — these power dependent dropdowns. | C22: When org structure changes
A23: LK_LocationMaster ⭐ | B23: All 18 Lao PDR provinces + 17 foreign postings, each expanded to district level (154 rows). Three flags auto-derive in Employee Master from this table: (1) Is Remote (Col G) → Remote Area Allowance. (2) Is Hazardous (Col H) → Hardship & Hazardous Allowance. (3) Is Foreign (derived from Country = Foreign/International) → Foreign Living Allowance. ► Update Col G or H when MoHA/MoF gazette revises province classification. DO NOT change Province Key (Col C) — it powers dependent district dropdowns. | C23: Per MoHA/MoF gazette
A24: LK_BankMaster | B24: 5 banks, 20 branches. Bank Name and Branch Name drive dependent dropdowns in Employee Master. Bank Branch Code (Col D) and SWIFT/BIC Code (Col E) are auto-looked up in Employee Master. ► Add new branches as new rows — keep bank name in Col A exactly matching existing entries. Col H (helper key) is auto-calculated — do not edit. | C24: When new branch added
A25: LK_AllowanceRates | B25: All cash allowance amounts and SSO/PIT-related rates. ► Update Col B (Amount) for any allowance when MoF issues revised rates. Note: Index Value (ຄ່າດັດສະນີ) is NO LONGER here — it is now in LK_GradeStep Col E. ► Update Row 26 (SSO Employee Rate %) and Row 27 (SSO Employer Rate %) when SSO revises rates. DO NOT change the allowance names in Col A — these are VLOOKUP keys used by PAYROLL_CALC. | C25: Per MoF circular / SSO decree
A26: LK_PIT | B26: Personal Income Tax progressive brackets for Lao PDR. ► Update Col D (Rate %) and Col F (Cumulative Tax at lower bound) if GDT/MoF revises tax slabs. PIT is calculated on Taxable Income = Gross Earnings minus SSO Employee Contribution. | C26: Per GDT/MoF order
A27: 4. EMPLOYEE MASTER — FIELD-BY-FIELD ENTRY GUIDE
A28: Element / Field | B28: Description | C28: Frequency / Trigger
A29: PERSONAL & EMPLOYMENT DETAILS (Cols A–L)
A30: Employee Code (Col A) | B30: Unique identifier — format LAO00001. Pre-populated in mock data. Do not duplicate. | C30: One-time, system assigned
A31: Title (Col B) | B31: Mr. / Ms. / Mrs. / Dr. | C31: On record
A32: First Name (Col C), Last Name (Col D) | B32: Employee's name in English. | C32: On record
A33: Gender (Col E) | B33: Dropdown: Male / Female. | C33: On record
A34: Date of Birth (Col F) | B34: DD-MMM-YYYY. Drives auto-calculation of Date of Retirement (age 60) in Col K. | C34: On record
A35: Date of Joining (Col I) | B35: Date employee joined government service. Drives auto-calculation of Years of Service (Col J). | C35: On record
A36: Years of Service (Col J) | B36: 🟢 AUTO — DATEDIF formula from Date of Joining to today. Do not edit. | C36: Automatic
A37: Date of Retirement (Col K) | B37: 🟢 AUTO — Date of Birth + 60 years. Do not edit. | C37: Automatic
A38: Employment Type (Col L) | B38: Dropdown: Permanent / Probationary / Contract / Intern. | C38: On joining / change
A39: GRADE & SALARY INPUTS (Cols M–Q)
A40: Position / Designation (Col M) | B40: 🔗 DEPENDENT DROPDOWN — shows positions for this employee's Profession Category (Col Z). Profession is auto-derived from Ministry via LK_OrgMaster. Select Ministry first, then choose the position title. | C40: On joining / promotion
...

Sheet NOTES
A1: =HYPERLINK("#HOME!A1","🏠 HOME") -> 🏠 HOME | C1: =HYPERLINK("#INSTRUCTIONS!A1","📋 GUIDE") -> 📋 GUIDE
A2: Plain language explanations for the users.
B3: WHAT IS THIS FILE?
B4: What is this toolkit? | C4: This Excel file is a payroll preparation tool for the Lao PDR Government. It holds personal, employment, and salary information for 500 civil servants (mock data). When the correct data is entered, it automatically calculates every employee's monthly salary, allowances, deductions, and take-home pay — without any manual arithmetic.
B6: YELLOW AND GREEN CELLS EXPLAINED
B7: Yellow cells — YOU fill these in | C7: Yellow cells are where staff enter or update data. Examples: Employee name, date of birth, date of joining government Education qualification and years of prior work experience Ministry, department, and division (select from dropdown) Service province (select from dropdown) Bank name and branch (select from dropdown) Has Spouse: Yes / No Number of eligible children (0 to 3) RULE: Yellow cells are the ONLY cells you should type into.
B8: Green cells — the file fills automatically | C8: Green cells contain formulas. You never need to type into them. Examples: Grade and Step — calculated from education + years of prior experience Profession Category — identified from the ministry the employee works in Is Remote Area / Is Hazardous — checked from the province of posting Is Foreign Posting — Yes if posted outside Lao PDR Basic Salary — Index Value times Multiplier (from the grade/step table) All allowances and deductions — from rates in master tables Net Salary — Gross Earnings minus total deductions RULE: NEVER type into a green cell. Doing so will break the formula.
B10: HOW SALARY IS CALCULATED — STEP BY STEP
B11: Step 1 — Grade and Step | C11: Every civil servant has a Grade (1 to 10) and a Step (1 to 10). Grade is based on your highest education level: Below Secondary = Grade 1 | Secondary School = Grade 2 Diploma = Grade 3 | Bachelor Degree = Grade 4 Master Degree = Grade 6 | Doctorate (PhD) = Grade 8 Step goes up by 1 for every 2 years of work experience BEFORE joining government. Example: Bachelor degree + 6 years prior experience = Grade 5, Step 4.
B12: Step 2 — Basic Salary | C12: Basic Salary = Index Value x Multiplier Index Value is a LAK amount set by MoF per grade: Grade 1 = 820,000 LAK | Grade 5 = 920,000 LAK | Grade 10 = 1,250,000 LAK Multiplier increases with each grade and step: Grade 1 Step 1 = 1.45x | Grade 10 Step 10 = 8.35x Example: Grade 4, Step 3 = 890,000 LAK x 3.10 = 2,759,000 LAK basic salary
B13: Step 3 — Allowances added on top | C13: These allowances are added to basic salary based on the employee's situation: Position Allowance — based on job title (General Staff up to Minister level) Years of Service Allowance — increases at 5, 10, 15, 20 and 25 years Teaching Allowance — for all Ministry of Education staff Medical Allowance — for all Ministry of Health staff NA Member Allowance — for National Assembly staff Remote Area Allowance — if posted to a remote province Hazardous Area Allowance — if posted to a UXO / security zone province Foreign Living Allowance — if posted abroad Fuel Benefit — if Grade 8 or above Spouse Benefit and Child Benefit — if married or have eligible children
B14: Step 4 — Deductions | C14: Two deductions are made from Gross Earnings: 1. SSO Employee Contribution = 5.5% of Basic Salary (paid to Social Security Organisation / MLSW) 2. Personal Income Tax (PIT) using progressive Lao PDR rates: Taxable Income = Gross Earnings minus SSO Contribution Up to 1,300,000 LAK = 0% (exempt) 1,300,001 to 5,000,000 LAK = 5% 5,000,001 to 10,000,000 LAK = 10% 10,000,001 to 20,000,000 LAK = 15% 20,000,001 to 40,000,000 LAK = 20% Above 40,000,000 LAK = 24%
B15: Step 5 — Net (Take-Home) Salary | C15: Net Salary = Gross Earnings minus Total Deductions (SSO + PIT). This is the amount credited to the employee's bank account each month. Shown in column AE of the PAYROLL_CALC sheet.
B17: DEPENDENT DROPDOWNS — HOW TO USE THEM
B18: How dropdowns work | C18: Many cells have a dropdown arrow. Click the cell, then click the arrow to see the list. The dropdowns are smart — selecting one option narrows choices in the next column: Ministry → Department → Division Country → Province → District Bank → Branch Example: Selecting Ministry of Health shows only MoH departments in the next dropdown. IMPORTANT: Always select in order — Ministry first, then Department, then Division. If you change Ministry after selecting Department, clear Department and re-select.
B19: Position dropdown | C19: The Position dropdown shows only positions relevant to the employee's profession. Ministry of Health staff — see: Doctor, Nurse, Pharmacist, etc. Ministry of Education staff — see: Teacher, Lecturer, Principal, etc. Finance Ministry staff — see: Accountant, Budget Officer, Tax Officer, etc. Profession is automatically detected from the Ministry selected.
B21: WHEN AND HOW TO UPDATE MASTER TABLES
B22: When MoF issues a new salary circular | C22: 1. Go to sheet LK_GradeStep. 2. Find the grade row(s) that changed. 3. Update Column E (Index Value) with the new LAK amount. Same amount for all grades: update all 10 grade rows (G1 through G10). Different amounts per grade: update each grade row separately. 4. All 500 basic salaries update instantly.
B23: When SSO changes the contribution rate | C23: 1. Go to sheet LK_AllowanceRates. 2. Find row 26 (SSO Employee Contribution Rate %). 3. Change the value in Column B to the new rate (e.g. enter 6 for 6%). 4. All 500 SSO deductions update automatically.
B24: When an employee is promoted | C24: 1. Go to EMPLOYEE_MASTER, find the employee's row. 2. If Prior Experience changed, update Column O. Grade and Step will auto-update from education + prior experience. 3. If position title changed, update Column M. Position Level (for allowance) will auto-derive from the new title. 4. PAYROLL_CALC reflects the new salary automatically.
B25: When an employee transfers to a new location | C25: 1. Go to EMPLOYEE_MASTER, find the employee's row. 2. Update Column W (Country), Column X (Province), Column Y (District). Use the dropdowns in order: Country, then Province, then District. 3. Is Remote, Is Hazardous, Is Foreign update automatically from Location Master. 4. Relevant allowances in PAYROLL_CALC turn on or off automatically.
B26: When a new employee joins | C26: 1. Go to EMPLOYEE_MASTER, scroll to row 504 (after last record). 2. Enter a new Employee Code (e.g. LAO00501). 3. Fill all yellow cells using the dropdowns. 4. Enter Prior Experience in Column O — Grade and Step auto-calculate. 5. Go to PAYROLL_CALC row 504, enter the employee code in Column A. 6. Copy the formula row from row 503 and paste (formulas only) into row 504.
B28: WHAT EACH SHEET DOES
B29: EMPLOYEE_MASTER | C29: Main data entry sheet. One row per employee, 45 columns. Covers personal details, employment, grade inputs, organisation, location, bank, and payroll flags. This is the sheet HR officers update most frequently.
B30: PAYROLL_CALC | C30: Monthly payroll output. All cells are formulas — nothing is typed here directly. Each row shows one employee's full salary breakdown: Basic Salary, 12 Allowances, Gross Earnings, SSO, PIT, and Net Salary. Row 504 shows grand totals for all 500 employees.
B31: LK_GradeStep | C31: Rate table for basic salary. 100 rows: 10 grades x 10 steps. Two editable values per row: Column D = Multiplier, Column E = Index Value in LAK. Basic Salary = Index Value x Multiplier.
B32: LK_OrgMaster | C32: Organisation hierarchy: all 18 ministries and provinces with their departments and divisions. Also records profession type and allowance types per organisation. Powers the Ministry to Department to Division dropdown chain.
B33: LK_LocationMaster | C33: Geography table: every province and district in Lao PDR, plus all foreign postings. Each province is tagged Remote (Yes/No) and Hazardous (Yes/No). Powers the Country to Province to District dropdown chain.
B34: LK_BankMaster | C34: Approved banks and branches: 5 banks, 20 branches. Includes branch codes and SWIFT codes. Powers the Bank to Branch dropdown. Branch code and SWIFT auto-fill when selected.
B35: DB_STTM | C35: Database Standard Technical Table Metadata. Technical reference for IT and database teams. Specifies column names, data types, lengths, constraints, primary/foreign keys, and derivation rules for all 9 tables in the payroll database schema.
B36: PROMPT_LOG | C36: Build history of this file. Records every user prompt that led to this toolkit, the version it produced, estimated generation time, and what was built or changed in each iteration.

Sheet EMPLOYEE_MASTER
A1: EMPLOYEE MASTER DATA — Lao PDR Government Payroll | 500 Mock Records | Yellow = Input | Green = Auto-Derived | 🔵 Blue = Audit Trail (Cols AT-AY)
A2: PERSONAL INFORMATION | I2: SERVICE DATES | L2: EMPLOYMENT & GRADE (P/Q AUTO) | R2: IDENTITY CARDS | T2: ORGANISATION ← Dependent Dropdowns | W2: SERVICE LOCATION ← Dependent Dropdowns + Auto-Derived | AD2: RESIDENTIAL ADDRESS | AJ2: BANK DETAILS ← Dependent Dropdowns + Auto-Derived | AO2: PAYROLL FLAGS (Auto-Derived) | AT2: 📅 AUDIT TRAIL — Effective Dates & Change History
A3: Employee Code | B3: Title | C3: First Name | D3: Last Name | E3: Gender | F3: Date of Birth | G3: Email Address | H3: Mobile Number | I3: Date of Joining | J3: Years of Service | K3: Date of Retirement | L3: Employment Type | M3: Position / Designation | N3: Education Qualification | O3: Prior Experience (Yrs before Govt) | P3: Grade | Q3: Step | R3: Civil Service Card ID | S3: Social Security No. | T3: Ministry / Province / Central Org | U3: Department | V3: Division | W3: Service Country | X3: Service Province / Posting | Y3: Service District | Z3: Profession Category | AA3: Is Remote Area | AB3: Is Foreign Posting | AC3: Is Hazardous Area | AD3: House No. | AE3: Street | AF3: Area / Baan | AG3: Province of Residence | AH3: PIN Code | AI3: Country | AJ3: Bank Name | AK3: Bank Branch | AL3: Bank Branch Code | AM3: Bank Account No. | AN3: SWIFT / BIC Code | AO3: Has Spouse | AP3: No. of Eligible Children (max 3) | AQ3: Position Level (for Allowance) | AR3: Is NA Member | AS3: Field Allowance Type | AT3: Effective From (Record Active Date) | AU3: Effective To (Superseded Date) | AV3: Record Created (Date) | AW3: Last Updated (Date) | AX3: Last Updated By (Name / Code) | AY3: Change Remarks
A4: LAO00001 | B4: Mrs. | C4: Khamsone | D4: Bounseng | E4: Female | F4: 25302 | G4: khamsone.bounseng@gov.la | H4: +856 20 94519179 | I4: 43300 | J4: =IFERROR(DATEDIF(I4,TODAY(),"Y"),0) -> 7 | K4: =IFERROR(DATE(YEAR(F4)+60,MONTH(F4),DAY(F4)),"") -> 47217 | L4: Permanent | M4: School Principal | N4: Bachelor's Degree | O4: 25 | P4: =IFERROR(SUMPRODUCT((LK_GradeDerivation!$A$4:$A$135=N4)*(IF(O4="",0,O4)>=LK_GradeDerivation!$B$4:$B$135)*(IF(O4="",0,O4)<=LK_GradeDerivation!$C$4:$C$135)*LK_GradeDerivation!$D$4:$D$135),1) -> 4 | Q4: =IFERROR(SUMPRODUCT((LK_GradeDerivation!$A$4:$A$135=N4)*(IF(O4="",0,O4)>=LK_GradeDerivation!$B$4:$B$135)*(IF(O4="",0,O4)<=LK_GradeDerivation!$C$4:$C$135)*LK_GradeDerivation!$E$4:$E$135),1) -> 13 | R4: CSC000001 | S4: SSO6266630 | T4: Ministry of Education and Sports (MoES) | U4: Department of Primary Education | V4: Curriculum Division | W4: Lao PDR | X4: Sekong | Y4: Lamam | Z4: =IFERROR(VLOOKUP(T4,LK_OrgMaster!$B$4:$H$89,5,FALSE()),"Administration") -> Teacher | AA4: =IFERROR(VLOOKUP(X4,LK_LocationMaster!$D$4:$G$157,4,FALSE()),"No") -> Yes | AB4: =IF(W4="Foreign / International","Yes","No") -> No | AC4: =IFERROR(VLOOKUP(X4,LK_LocationMaster!$D$4:$H$157,5,FALSE()),"No") -> Yes | AD4: No. 738 | AE4: Street 20 | AF4: Baan Kaisone | AG4: Phongsali | AH4: 769100 | AI4: Lao PDR | AJ4: BIC Bank Laos | AK4: BIC Head Office - Vientiane | AL4: =IFERROR(INDEX(LK_BankMaster!$D$4:$D$23,MATCH(AJ4&"|"&AK4,LK_BankMaster!$H$4:$H$23,0)),"") | AM4: 491079829 | AN4: =IFERROR(VLOOKUP(AJ4,LK_BankMaster!$A$4:$E$23,5,FALSE()),"") | AO4: Yes | AP4: 2 | AQ4: =IF(ISNUMBER(SEARCH("Deputy Minister",M4)),"Position Allowance - Deputy Minister",IF(AND(ISNUMBER(SEARCH("Minister",M4)),NOT(ISNUMBER(SEARCH("Deputy",M4)))),"Position Allowance - Minister",IF(ISNUMBER(SEARCH("Deputy Director",M4)),"Position Allowance - Deputy Director",IF(AND(ISNUMBER(SEARCH("Director",M4)),NOT(ISNUMBER(SEARCH("Deputy",M4)))),"Position Allowance - Director",IF(ISNUMBER(SEARCH("Division Chief",M4)),"Position Allowance - Division Chief",IF(ISNUMBER(SEARCH("Section Chief",M4)),"Position Allowance - Section Chief","Position Allowance - General Staff")))))) -> Position Allowance - General Staff | AR4: =IFERROR(VLOOKUP(T4,LK_OrgMaster!$B$4:$G$89,6,FALSE()),"No") -> No | AS4: =IFERROR(VLOOKUP(T4,LK_OrgMaster!$B$4:$H$89,7,FALSE()),"None") -> Teaching | AT4: 43300 | AV4: 43300 | AW4: 46023 | AX4: Initial Load | AY4: Record created during payroll system initial data load (Jan 2026).
A5: LAO00002 | B5: Ms. | C5: Sisamone | D5: Vilayvong | E5: Female | F5: 33143 | G5: sisamone.vilayvon@gov.la | H5: +856 20 81204829 | I5: 32641 | J5: =IFERROR(DATEDIF(I5,TODAY(),"Y"),0) -> 36 | K5: =IFERROR(DATE(YEAR(F5)+60,MONTH(F5),DAY(F5)),"") -> 55058 | L5: Permanent | M5: Senior Officer | N5: Master's Degree | O5: 0 | P5: =IFERROR(SUMPRODUCT((LK_GradeDerivation!$A$4:$A$135=N5)*(IF(O5="",0,O5)>=LK_GradeDerivation!$B$4:$B$135)*(IF(O5="",0,O5)<=LK_GradeDerivation!$C$4:$C$135)*LK_GradeDerivation!$D$4:$D$135),1) -> 5 | Q5: =IFERROR(SUMPRODUCT((LK_GradeDerivation!$A$4:$A$135=N5)*(IF(O5="",0,O5)>=LK_GradeDerivation!$B$4:$B$135)*(IF(O5="",0,O5)<=LK_GradeDerivation!$C$4:$C$135)*LK_GradeDerivation!$E$4:$E$135),1) -> 1 | R5: CSC000002 | S5: SSO6406444 | T5: National Assembly (NA) | U5: Committee on Economy & Finance | V5: Administrative Division | W5: Lao PDR | X5: Vientiane Capital | Y5: Chanthabouli | Z5: =IFERROR(VLOOKUP(T5,LK_OrgMaster!$B$4:$H$89,5,FALSE()),"Administration") -> Administration | AA5: =IFERROR(VLOOKUP(X5,LK_LocationMaster!$D$4:$G$157,4,FALSE()),"No") -> No | AB5: =IF(W5="Foreign / International","Yes","No") -> No | AC5: =IFERROR(VLOOKUP(X5,LK_LocationMaster!$D$4:$H$157,5,FALSE()),"No") -> No | AD5: No. 453 | AE5: Setthathirath Road | AF5: Baan Nongping | AG5: Sayabouli | AH5: 875200 | AI5: Lao PDR | AJ5: Agriculture Promotion Bank (APB) | AK5: APB Luang Prabang Branch | AL5: =IFERROR(INDEX(LK_BankMaster!$D$4:$D$23,MATCH(AJ5&"|"&AK5,LK_BankMaster!$H$4:$H$23,0)),"") | AM5: 325681936 | AN5: =IFERROR(VLOOKUP(AJ5,LK_BankMaster!$A$4:$E$23,5,FALSE()),"") | AO5: Yes | AP5: 3 | AQ5: =IF(ISNUMBER(SEARCH("Deputy Minister",M5)),"Position Allowance - Deputy Minister",IF(AND(ISNUMBER(SEARCH("Minister",M5)),NOT(ISNUMBER(SEARCH("Deputy",M5)))),"Position Allowance - Minister",IF(ISNUMBER(SEARCH("Deputy Director",M5)),"Position Allowance - Deputy Director",IF(AND(ISNUMBER(SEARCH("Director",M5)),NOT(ISNUMBER(SEARCH("Deputy",M5)))),"Position Allowance - Director",IF(ISNUMBER(SEARCH("Division Chief",M5)),"Position Allowance - Division Chief",IF(ISNUMBER(SEARCH("Section Chief",M5)),"Position Allowance - Section Chief","Position Allowance - General Staff")))))) -> Position Allowance - General Staff | AR5: =IFERROR(VLOOKUP(T5,LK_OrgMaster!$B$4:$G$89,6,FALSE()),"No") -> Yes | AS5: =IFERROR(VLOOKUP(T5,LK_OrgMaster!$B$4:$H$89,7,FALSE()),"None") -> None | AT5: 32641 | AV5: 32641 | AW5: 46023 | AX5: Initial Load | AY5: Record created during payroll system initial data load (Jan 2026).
A6: LAO00003 | B6: Dr. | C6: Keovilay | D6: Sisouvath | E6: Male | F6: 29953 | G6: keovilay.sisouvat@gov.la | H6: +856 20 98207378 | I6: 40638 | J6: =IFERROR(DATEDIF(I6,TODAY(),"Y"),0) -> 14 | K6: =IFERROR(DATE(YEAR(F6)+60,MONTH(F6),DAY(F6)),"") -> 51868 | L6: Permanent | M6: Nurse | N6: Secondary School (Grade 12) | O6: 11 | P6: =IFERROR(SUMPRODUCT((LK_GradeDerivation!$A$4:$A$135=N6)*(IF(O6="",0,O6)>=LK_GradeDerivation!$B$4:$B$135)*(IF(O6="",0,O6)<=LK_GradeDerivation!$C$4:$C$135)*LK_GradeDerivation!$D$4:$D$135),1) -> 2 | Q6: =IFERROR(SUMPRODUCT((LK_GradeDerivation!$A$4:$A$135=N6)*(IF(O6="",0,O6)>=LK_GradeDerivation!$B$4:$B$135)*(IF(O6="",0,O6)<=LK_GradeDerivation!$C$4:$C$135)*LK_GradeDerivation!$E$4:$E$135),1) -> 6 | R6: CSC000003 | S6: SSO4262081 | T6: Ministry of Health (MoH) | U6: Department of Planning & Finance | V6: Health Financing Division | W6: Lao PDR | X6: Champasak | Y6: Khong | Z6: =IFERROR(VLOOKUP(T6,LK_OrgMaster!$B$4:$H$89,5,FALSE()),"Administration") -> Medical | AA6: =IFERROR(VLOOKUP(X6,LK_LocationMaster!$D$4:$G$157,4,FALSE()),"No") -> No | AB6: =IF(W6="Foreign / International","Yes","No") -> No | AC6: =IFERROR(VLOOKUP(X6,LK_LocationMaster!$D$4:$H$157,5,FALSE()),"No") -> No | AD6: No. 507 | AE6: Setthathirath Road | AF6: Baan Dongpalane | AG6: Huaphan | AH6: 109000 | AI6: Lao PDR | AJ6: BCEL (Banque pour le Commerce Exterieur Lao) | AK6: BCEL Oudomxay Branch | AL6: =IFERROR(INDEX(LK_BankMaster!$D$4:$D$23,MATCH(AJ6&"|"&AK6,LK_BankMaster!$H$4:$H$23,0)),"") | AM6: 545002643 | AN6: =IFERROR(VLOOKUP(AJ6,LK_BankMaster!$A$4:$E$23,5,FALSE()),"") | AO6: No | AP6: 0 | AQ6: =IF(ISNUMBER(SEARCH("Deputy Minister",M6)),"Position Allowance - Deputy Minister",IF(AND(ISNUMBER(SEARCH("Minister",M6)),NOT(ISNUMBER(SEARCH("Deputy",M6)))),"Position Allowance - Minister",IF(ISNUMBER(SEARCH("Deputy Director",M6)),"Position Allowance - Deputy Director",IF(AND(ISNUMBER(SEARCH("Director",M6)),NOT(ISNUMBER(SEARCH("Deputy",M6)))),"Position Allowance - Director",IF(ISNUMBER(SEARCH("Division Chief",M6)),"Position Allowance - Division Chief",IF(ISNUMBER(SEARCH("Section Chief",M6)),"Position Allowance - Section Chief","Position Allowance - General Staff")))))) -> Position Allowance - General Staff | AR6: =IFERROR(VLOOKUP(T6,LK_OrgMaster!$B$4:$G$89,6,FALSE()),"No") -> No | AS6: =IFERROR(VLOOKUP(T6,LK_OrgMaster!$B$4:$H$89,7,FALSE()),"None") -> Medical | AT6: 40638 | AV6: 40638 | AW6: 46023 | AX6: Initial Load | AY6: Record created during payroll system initial data load (Jan 2026).
A7: LAO00004 | B7: Dr. | C7: Sengphet | D7: Sengmixay | E7: Male | F7: 31646 | G7: sengphet.sengmixa@gov.la | H7: +856 20 78638087 | I7: 43317 | J7: =IFERROR(DATEDIF(I7,TODAY(),"Y"),0) -> 7 | K7: =IFERROR(DATE(YEAR(F7)+60,MONTH(F7),DAY(F7)),"") -> 53561 | L7: Permanent | M7: Primary School Teacher | N7: Bachelor's Degree | O7: 9 | P7: =IFERROR(SUMPRODUCT((LK_GradeDerivation!$A$4:$A$135=N7)*(IF(O7="",0,O7)>=LK_GradeDerivation!$B$4:$B$135)*(IF(O7="",0,O7)<=LK_GradeDerivation!$C$4:$C$135)*LK_GradeDerivation!$D$4:$D$135),1) -> 4 | Q7: =IFERROR(SUMPRODUCT((LK_GradeDerivation!$A$4:$A$135=N7)*(IF(O7="",0,O7)>=LK_GradeDerivation!$B$4:$B$135)*(IF(O7="",0,O7)<=LK_GradeDerivation!$C$4:$C$135)*LK_GradeDerivation!$E$4:$E$135),1) -> 5 | R7: CSC000004 | S7: SSO9468772 | T7: Ministry of Education and Sports (MoES) | U7: Department of Primary Education | V7: Administrative Division | W7: Lao PDR | X7: Xaysomboun | Y7: Longcheng | Z7: =IFERROR(VLOOKUP(T7,LK_OrgMaster!$B$4:$H$89,5,FALSE()),"Administration") -> Teacher | AA7: =IFERROR(VLOOKUP(X7,LK_LocationMaster!$D$4:$G$157,4,FALSE()),"No") -> Yes | AB7: =IF(W7="Foreign / International","Yes","No") -> No | AC7: =IFERROR(VLOOKUP(X7,LK_LocationMaster!$D$4:$H$157,5,FALSE()),"No") -> Yes | AD7: No. 919 | AE7: Nong Bone Road | AF7: Baan Saphanthong | AG7: Sayabouli | AH7: 524600 | AI7: Lao PDR | AJ7: Agriculture Promotion Bank (APB) | AK7: APB Khammuane Branch | AL7: =IFERROR(INDEX(LK_BankMaster!$D$4:$D$23,MATCH(AJ7&"|"&AK7,LK_BankMaster!$H$4:$H$23,0)),"") | AM7: 757830420 | AN7: =IFERROR(VLOOKUP(AJ7,LK_BankMaster!$A$4:$E$23,5,FALSE()),"") | AO7: No | AP7: 0 | AQ7: =IF(ISNUMBER(SEARCH("Deputy Minister",M7)),"Position Allowance - Deputy Minister",IF(AND(ISNUMBER(SEARCH("Minister",M7)),NOT(ISNUMBER(SEARCH("Deputy",M7)))),"Position Allowance - Minister",IF(ISNUMBER(SEARCH("Deputy Director",M7)),"Position Allowance - Deputy Director",IF(AND(ISNUMBER(SEARCH("Director",M7)),NOT(ISNUMBER(SEARCH("Deputy",M7)))),"Position Allowance - Director",IF(ISNUMBER(SEARCH("Division Chief",M7)),"Position Allowance - Division Chief",IF(ISNUMBER(SEARCH("Section Chief",M7)),"Position Allowance - Section Chief","Position Allowance - General Staff")))))) -> Position Allowance - General Staff | AR7: =IFERROR(VLOOKUP(T7,LK_OrgMaster!$B$4:$G$89,6,FALSE()),"No") -> No | AS7: =IFERROR(VLOOKUP(T7,LK_OrgMaster!$B$4:$H$89,7,FALSE()),"None") -> Teaching | AT7: 43317 | AV7: 43317 | AW7: 46023 | AX7: Initial Load | AY7: Record created during payroll system initial data load (Jan 2026).
A8: LAO00005 | B8: Mrs. | C8: Vilaychith | D8: Phommachack | E8: Female | F8: 30485 | G8: vilaychith.phommach@gov.la | H8: +856 20 72205074 | I8: 40309 | J8: =IFERROR(DATEDIF(I8,TODAY(),"Y"),0) -> 15 | K8: =IFERROR(DATE(YEAR(F8)+60,MONTH(F8),DAY(F8)),"") -> 52400 | L8: Permanent | M8: Dental Officer | N8: Secondary School (Grade 12) | O8: 8 | P8: =IFERROR(SUMPRODUCT((LK_GradeDerivation!$A$4:$A$135=N8)*(IF(O8="",0,O8)>=LK_GradeDerivation!$B$4:$B$135)*(IF(O8="",0,O8)<=LK_GradeDerivation!$C$4:$C$135)*LK_GradeDerivation!$D$4:$D$135),1) -> 2 | Q8: =IFERROR(SUMPRODUCT((LK_GradeDerivation!$A$4:$A$135=N8)*(IF(O8="",0,O8)>=LK_GradeDerivation!$B$4:$B$135)*(IF(O8="",0,O8)<=LK_GradeDerivation!$C$4:$C$135)*LK_GradeDerivation!$E$4:$E$135),1) -> 5 | R8: CSC000005 | S8: SSO7838382 | T8: Ministry of Health (MoH) | U8: Department of Hygiene & Health Promotion | V8: Environmental Health Division | W8: Lao PDR | X8: Bokeo | Y8: Ton Pheung | Z8: =IFERROR(VLOOKUP(T8,LK_OrgMaster!$B$4:$H$89,5,FALSE()),"Administration") -> Medical | AA8: =IFERROR(VLOOKUP(X8,LK_LocationMaster!$D$4:$G$157,4,FALSE()),"No") -> Yes | AB8: =IF(W8="Foreign / International","Yes","No") -> No | AC8: =IFERROR(VLOOKUP(X8,LK_LocationMaster!$D$4:$H$157,5,FALSE()),"No") -> No | AD8: No. 426 | AE8: Setthathirath Road | AF8: Baan Phonthong | AG8: Sayabouli | AH8: 738100 | AI8: Lao PDR | AJ8: Joint Development Bank (JDB) | AK8: JDB Vientiane Branch | AL8: =IFERROR(INDEX(LK_BankMaster!$D$4:$D$23,MATCH(AJ8&"|"&AK8,LK_BankMaster!$H$4:$H$23,0)),"") | AM8: 858511779 | AN8: =IFERROR(VLOOKUP(AJ8,LK_BankMaster!$A$4:$E$23,5,FALSE()),"") | AO8: Yes | AP8: 3 | AQ8: =IF(ISNUMBER(SEARCH("Deputy Minister",M8)),"Position Allowance - Deputy Minister",IF(AND(ISNUMBER(SEARCH("Minister",M8)),NOT(ISNUMBER(SEARCH("Deputy",M8)))),"Position Allowance - Minister",IF(ISNUMBER(SEARCH("Deputy Director",M8)),"Position Allowance - Deputy Director",IF(AND(ISNUMBER(SEARCH("Director",M8)),NOT(ISNUMBER(SEARCH("Deputy",M8)))),"Position Allowance - Director",IF(ISNUMBER(SEARCH("Division Chief",M8)),"Position Allowance - Division Chief",IF(ISNUMBER(SEARCH("Section Chief",M8)),"Position Allowance - Section Chief","Position Allowance - General Staff")))))) -> Position Allowance - General Staff | AR8: =IFERROR(VLOOKUP(T8,LK_OrgMaster!$B$4:$G$89,6,FALSE()),"No") -> No | AS8: =IFERROR(VLOOKUP(T8,LK_OrgMaster!$B$4:$H$89,7,FALSE()),"None") -> Medical | AT8: 40309 | AV8: 40309 | AW8: 46023 | AX8: Initial Load | AY8: Record created during payroll system initial data load (Jan 2026).
A9: LAO00006 | B9: Mrs. | C9: Phonethip | D9: Phommavong | E9: Female | F9: 27663 | G9: phonethip.phommavo@gov.la | H9: +856 20 94887348 | I9: 33596 | J9: =IFERROR(DATEDIF(I9,TODAY(),"Y"),0) -> 34 | K9: =IFERROR(DATE(YEAR(F9)+60,MONTH(F9),DAY(F9)),"") -> 49578 | L9: Permanent | M9: Senior Doctor | N9: Master's Degree | O9: 0 | P9: =IFERROR(SUMPRODUCT((LK_GradeDerivation!$A$4:$A$135=N9)*(IF(O9="",0,O9)>=LK_GradeDerivation!$B$4:$B$135)*(IF(O9="",0,O9)<=LK_GradeDerivation!$C$4:$C$135)*LK_GradeDerivation!$D$4:$D$135),1) -> 5 | Q9: =IFERROR(SUMPRODUCT((LK_GradeDerivation!$A$4:$A$135=N9)*(IF(O9="",0,O9)>=LK_GradeDerivation!$B$4:$B$135)*(IF(O9="",0,O9)<=LK_GradeDerivation!$C$4:$C$135)*LK_GradeDerivation!$E$4:$E$135),1) -> 1 | R9: CSC000006 | S9: SSO6639317 | T9: Ministry of Health (MoH) | U9: Department of Personnel & Organisation | V9: Recruitment Division | W9: Lao PDR | X9: Sayabouli | Y9: Kenethao | Z9: =IFERROR(VLOOKUP(T9,LK_OrgMaster!$B$4:$H$89,5,FALSE()),"Administration") -> Medical | AA9: =IFERROR(VLOOKUP(X9,LK_LocationMaster!$D$4:$G$157,4,FALSE()),"No") -> Yes | AB9: =IF(W9="Foreign / International","Yes","No") -> No | AC9: =IFERROR(VLOOKUP(X9,LK_LocationMaster!$D$4:$H$157,5,FALSE()),"No") -> No | AD9: No. 742 | AE9: Nong Bone Road | AF9: Baan Dongpalane | AG9: Huaphan | AH9: 975100 | AI9: Lao PDR | AJ9: Lao Development Bank (LDB) | AK9: LDB Pakse Branch | AL9: =IFERROR(INDEX(LK_BankMaster!$D$4:$D$23,MATCH(AJ9&"|"&AK9,LK_BankMaster!$H$4:$H$23,0)),"") | AM9: 567975319 | AN9: =IFERROR(VLOOKUP(AJ9,LK_BankMaster!$A$4:$E$23,5,FALSE()),"") | AO9: Yes | AP9: 3 | AQ9: =IF(ISNUMBER(SEARCH("Deputy Minister",M9)),"Position Allowance - Deputy Minister",IF(AND(ISNUMBER(SEARCH("Minister",M9)),NOT(ISNUMBER(SEARCH("Deputy",M9)))),"Position Allowance - Minister",IF(ISNUMBER(SEARCH("Deputy Director",M9)),"Position Allowance - Deputy Director",IF(AND(ISNUMBER(SEARCH("Director",M9)),NOT(ISNUMBER(SEARCH("Deputy",M9)))),"Position Allowance - Director",IF(ISNUMBER(SEARCH("Division Chief",M9)),"Position Allowance - Division Chief",IF(ISNUMBER(SEARCH("Section Chief",M9)),"Position Allowance - Section Chief","Position Allowance - General Staff")))))) -> Position Allowance - General Staff | AR9: =IFERROR(VLOOKUP(T9,LK_OrgMaster!$B$4:$G$89,6,FALSE()),"No") -> No | AS9: =IFERROR(VLOOKUP(T9,LK_OrgMaster!$B$4:$H$89,7,FALSE()),"None") -> Medical | AT9: 33596 | AV9: 33596 | AW9: 46023 | AX9: Initial Load | AY9: Record created during payroll system initial data load (Jan 2026).
A10: LAO00007 | B10: Dr. | C10: Phonesavanh | D10: Soulinthong | E10: Male | F10: 33031 | G10: phonesavanh.soulinth@gov.la | H10: +856 20 51300790 | I10: 44694 | J10: =IFERROR(DATEDIF(I10,TODAY(),"Y"),0) -> 3 | K10: =IFERROR(DATE(YEAR(F10)+60,MONTH(F10),DAY(F10)),"") -> 54946 | L10: Permanent | M10: Department Director | N10: Master's Degree | O10: 6 | P10: =IFERROR(SUMPRODUCT((LK_GradeDerivation!$A$4:$A$135=N10)*(IF(O10="",0,O10)>=LK_GradeDerivation!$B$4:$B$135)*(IF(O10="",0,O10)<=LK_GradeDerivation!$C$4:$C$135)*LK_GradeDerivation!$D$4:$D$135),1) -> 5 | Q10: =IFERROR(SUMPRODUCT((LK_GradeDerivation!$A$4:$A$135=N10)*(IF(O10="",0,O10)>=LK_GradeDerivation!$B$4:$B$135)*(IF(O10="",0,O10)<=LK_GradeDerivation!$C$4:$C$135)*LK_GradeDerivation!$E$4:$E$135),1) -> 4 | R10: CSC000007 | S10: SSO8890439 | T10: Ministry of Industry & Commerce (MoIC) | U10: Department of Industry | V10: Administrative Division | W10: Lao PDR | X10: Bolikhamxay | Y10: Bolikhanh | Z10: =IFERROR(VLOOKUP(T10,LK_OrgMaster!$B$4:$H$89,5,FALSE()),"Administration") -> Administration | AA10: =IFERROR(VLOOKUP(X10,LK_LocationMaster!$D$4:$G$157,4,FALSE()),"No") -> No | AB10: =IF(W10="Foreign / International","Yes","No") -> No | AC10: =IFERROR(VLOOKUP(X10,LK_LocationMaster!$D$4:$H$157,5,FALSE()),"No") -> No | AD10: No. 975 | AE10: Setthathirath Road | AF10: Baan Nongchanh | AG10: Vientiane Capital | AH10: 165900 | AI10: Lao PDR | AJ10: Agriculture Promotion Bank (APB) | AK10: APB Khammuane Branch | AL10: =IFERROR(INDEX(LK_BankMaster!$D$4:$D$23,MATCH(AJ10&"|"&AK10,LK_BankMaster!$H$4:$H$23,0)),"") | AM10: 370874491 | AN10: =IFERROR(VLOOKUP(AJ10,LK_BankMaster!$A$4:$E$23,5,FALSE()),"") | AO10: No | AP10: 0 | AQ10: =IF(ISNUMBER(SEARCH("Deputy Minister",M10)),"Position Allowance - Deputy Minister",IF(AND(ISNUMBER(SEARCH("Minister",M10)),NOT(ISNUMBER(SEARCH("Deputy",M10)))),"Position Allowance - Minister",IF(ISNUMBER(SEARCH("Deputy Director",M10)),"Position Allowance - Deputy Director",IF(AND(ISNUMBER(SEARCH("Director",M10)),NOT(ISNUMBER(SEARCH("Deputy",M10)))),"Position Allowance - Director",IF(ISNUMBER(SEARCH("Division Chief",M10)),"Position Allowance - Division Chief",IF(ISNUMBER(SEARCH("Section Chief",M10)),"Position Allowance - Section Chief","Position Allowance - General Staff")))))) -> Position Allowance - Director | AR10: =IFERROR(VLOOKUP(T10,LK_OrgMaster!$B$4:$G$89,6,FALSE()),"No") -> No | AS10: =IFERROR(VLOOKUP(T10,LK_OrgMaster!$B$4:$H$89,7,FALSE()),"None") -> None | AT10: 44694 | AV10: 44694 | AW10: 46023 | AX10: Initial Load | AY10: Record created during payroll system initial data load (Jan 2026).
A11: LAO00008 | B11: Mr. | C11: Bounma | D11: Phongphichith | E11: Male | F11: 26168 | G11: bounma.phongphi@gov.la | H11: +856 20 57254384 | I11: 43380 | J11: =IFERROR(DATEDIF(I11,TODAY(),"Y"),0) -> 7 | K11: =IFERROR(DATE(YEAR(F11)+60,MONTH(F11),DAY(F11)),"") -> 48083 | L11: Permanent | M11: IT Officer | N11: Secondary School (Grade 12) | O11: 25 | P11: =IFERROR(SUMPRODUCT((LK_GradeDerivation!$A$4:$A$135=N11)*(IF(O11="",0,O11)>=LK_GradeDerivation!$B$4:$B$135)*(IF(O11="",0,O11)<=LK_GradeDerivation!$C$4:$C$135)*LK_GradeDerivation!$D$4:$D$135),1) -> 2 | Q11: =IFERROR(SUMPRODUCT((LK_GradeDerivation!$A$4:$A$135=N11)*(IF(O11="",0,O11)>=LK_GradeDerivation!$B$4:$B$135)*(IF(O11="",0,O11)<=LK_GradeDerivation!$C$4:$C$135)*LK_GradeDerivation!$E$4:$E$135),1) -> 13 | R11: CSC000008 | S11: SSO6218367 | T11: Ministry of Public Works & Transport (MPWT) | U11: Department of Roads | V11: Road Construction Division | W11: Lao PDR | X11: Khammuane | Y11: Nongbok | Z11: =IFERROR(VLOOKUP(T11,LK_OrgMaster!$B$4:$H$89,5,FALSE()),"Administration") -> Technical | AA11: =IFERROR(VLOOKUP(X11,LK_LocationMaster!$D$4:$G$157,4,FALSE()),"No") -> No | AB11: =IF(W11="Foreign / International","Yes","No") -> No | AC11: =IFERROR(VLOOKUP(X11,LK_LocationMaster!$D$4:$H$157,5,FALSE()),"No") -> Yes | AD11: No. 952 | AE11: Street 20 | AF11: Baan Phonthong | AG11: Vientiane Capital | AH11: 749800 | AI11: Lao PDR | AJ11: BIC Bank Laos | AK11: BIC Head Office - Vientiane | AL11: =IFERROR(INDEX(LK_BankMaster!$D$4:$D$23,MATCH(AJ11&"|"&AK11,LK_BankMaster!$H$4:$H$23,0)),"") | AM11: 935147672 | AN11: =IFERROR(VLOOKUP(AJ11,LK_BankMaster!$A$4:$E$23,5,FALSE()),"") | AO11: No | AP11: 0 | AQ11: =IF(ISNUMBER(SEARCH("Deputy Minister",M11)),"Position Allowance - Deputy Minister",IF(AND(ISNUMBER(SEARCH("Minister",M11)),NOT(ISNUMBER(SEARCH("Deputy",M11)))),"Position Allowance - Minister",IF(ISNUMBER(SEARCH("Deputy Director",M11)),"Position Allowance - Deputy Director",IF(AND(ISNUMBER(SEARCH("Director",M11)),NOT(ISNUMBER(SEARCH("Deputy",M11)))),"Position Allowance - Director",IF(ISNUMBER(SEARCH("Division Chief",M11)),"Position Allowance - Division Chief",IF(ISNUMBER(SEARCH("Section Chief",M11)),"Position Allowance - Section Chief","Position Allowance - General Staff")))))) -> Position Allowance - General Staff | AR11: =IFERROR(VLOOKUP(T11,LK_OrgMaster!$B$4:$G$89,6,FALSE()),"No") -> No | AS11: =IFERROR(VLOOKUP(T11,LK_OrgMaster!$B$4:$H$89,7,FALSE()),"None") -> None | AT11: 43380 | AV11: 43380 | AW11: 46023 | AX11: Initial Load | AY11: Record created during payroll system initial data load (Jan 2026).
A12: LAO00009 | B12: Mr. | C12: Khanthavy | D12: Sengmixay | E12: Male | F12: 29963 | G12: khanthavy.sengmixa@gov.la | H12: +856 20 57082593 | I12: 43399 | J12: =IFERROR(DATEDIF(I12,TODAY(),"Y"),0) -> 7 | K12: =IFERROR(DATE(YEAR(F12)+60,MONTH(F12),DAY(F12)),"") -> 51878 | L12: Permanent | M12: Nurse | N12: Bachelor's Degree | O12: 14 | P12: =IFERROR(SUMPRODUCT((LK_GradeDerivation!$A$4:$A$135=N12)*(IF(O12="",0,O12)>=LK_GradeDerivation!$B$4:$B$135)*(IF(O12="",0,O12)<=LK_GradeDerivation!$C$4:$C$135)*LK_GradeDerivation!$D$4:$D$135),1) -> 4 | Q12: =IFERROR(SUMPRODUCT((LK_GradeDerivation!$A$4:$A$135=N12)*(IF(O12="",0,O12)>=LK_GradeDerivation!$B$4:$B$135)*(IF(O12="",0,O12)<=LK_GradeDerivation!$C$4:$C$135)*LK_GradeDerivation!$E$4:$E$135),1) -> 8 | R12: CSC000009 | S12: SSO9224219 | T12: Ministry of Health (MoH) | U12: Department of Planning & Finance | V12: Health Financing Division | W12: Lao PDR | X12: Khammuane | Y12: Mahaxay | Z12: =IFERROR(VLOOKUP(T12,LK_OrgMaster!$B$4:$H$89,5,FALSE()),"Administration") -> Medical | AA12: =IFERROR(VLOOKUP(X12,LK_LocationMaster!$D$4:$G$157,4,FALSE()),"No") -> No | AB12: =IF(W12="Foreign / International","Yes","No") -> No | AC12: =IFERROR(VLOOKUP(X12,LK_LocationMaster!$D$4:$H$157,5,FALSE()),"No") -> Yes | AD12: No. 984 | AE12: Nong Bone Road | AF12: Baan Dongpalane | AG12: Huaphan | AH12: 813500 | AI12: Lao PDR | AJ12: BIC Bank Laos | AK12: BIC Head Office - Vientiane | AL12: =IFERROR(INDEX(LK_BankMaster!$D$4:$D$23,MATCH(AJ12&"|"&AK12,LK_BankMaster!$H$4:$H$23,0)),"") | AM12: 113585139 | AN12: =IFERROR(VLOOKUP(AJ12,LK_BankMaster!$A$4:$E$23,5,FALSE()),"") | AO12: No | AP12: 0 | AQ12: =IF(ISNUMBER(SEARCH("Deputy Minister",M12)),"Position Allowance - Deputy Minister",IF(AND(ISNUMBER(SEARCH("Minister",M12)),NOT(ISNUMBER(SEARCH("Deputy",M12)))),"Position Allowance - Minister",IF(ISNUMBER(SEARCH("Deputy Director",M12)),"Position Allowance - Deputy Director",IF(AND(ISNUMBER(SEARCH("Director",M12)),NOT(ISNUMBER(SEARCH("Deputy",M12)))),"Position Allowance - Director",IF(ISNUMBER(SEARCH("Division Chief",M12)),"Position Allowance - Division Chief",IF(ISNUMBER(SEARCH("Section Chief",M12)),"Position Allowance - Section Chief","Position Allowance - General Staff")))))) -> Position Allowance - General Staff | AR12: =IFERROR(VLOOKUP(T12,LK_OrgMaster!$B$4:$G$89,6,FALSE()),"No") -> No | AS12: =IFERROR(VLOOKUP(T12,LK_OrgMaster!$B$4:$H$89,7,FALSE()),"None") -> Medical | AT12: 43399 | AV12: 43399 | AW12: 46023 | AX12: Initial Load | AY12: Record created during payroll system initial data load (Jan 2026).
A13: LAO00010 | B13: Dr. | C13: Manyvone | D13: Phiaylack | E13: Female | F13: 29806 | G13: manyvone.phiaylac@gov.la | H13: +856 20 67337736 | I13: 40218 | J13: =IFERROR(DATEDIF(I13,TODAY(),"Y"),0) -> 16 | K13: =IFERROR(DATE(YEAR(F13)+60,MONTH(F13),DAY(F13)),"") -> 51721 | L13: Permanent | M13: Senior Legal Advisor | N13: Master's Degree | O13: 3 | P13: =IFERROR(SUMPRODUCT((LK_GradeDerivation!$A$4:$A$135=N13)*(IF(O13="",0,O13)>=LK_GradeDerivation!$B$4:$B$135)*(IF(O13="",0,O13)<=LK_GradeDerivation!$C$4:$C$135)*LK_GradeDerivation!$D$4:$D$135),1) -> 5 | Q13: =IFERROR(SUMPRODUCT((LK_GradeDerivation!$A$4:$A$135=N13)*(IF(O13="",0,O13)>=LK_GradeDerivation!$B$4:$B$135)*(IF(O13="",0,O13)<=LK_GradeDerivation!$C$4:$C$135)*LK_GradeDerivation!$E$4:$E$135),1) -> 2 | R13: CSC000010 | S13: SSO6952975 | T13: Ministry of Justice (MoJ) | U13: Department of Judicial Administration | V13: Legal Aid Division | W13: Lao PDR | X13: Savannakhet | Y13: Champhone | Z13: =IFERROR(VLOOKUP(T13,LK_OrgMaster!$B$4:$H$89,5,FALSE()),"Administration") -> Legal | AA13: =IFERROR(VLOOKUP(X13,LK_LocationMaster!$D$4:$G$157,4,FALSE()),"No") -> No | AB13: =IF(W13="Foreign / International","Yes","No") -> No | AC13: =IFERROR(VLOOKUP(X13,LK_LocationMaster!$D$4:$H$157,5,FALSE()),"No") -> Yes | AD13: No. 287 | AE13: Samsenthai Road | AF13: Baan Nongping | AG13: Luang Prabang | AH13: 116600 | AI13: Lao PDR | AJ13: BCEL (Banque pour le Commerce Exterieur Lao) | AK13: BCEL Oudomxay Branch | AL13: =IFERROR(INDEX(LK_BankMaster!$D$4:$D$23,MATCH(AJ13&"|"&AK13,LK_BankMaster!$H$4:$H$23,0)),"") | AM13: 448981305 | AN13: =IFERROR(VLOOKUP(AJ13,LK_BankMaster!$A$4:$E$23,5,FALSE()),"") | AO13: Yes | AP13: 1 | AQ13: =IF(ISNUMBER(SEARCH("Deputy Minister",M13)),"Position Allowance - Deputy Minister",IF(AND(ISNUMBER(SEARCH("Minister",M13)),NOT(ISNUMBER(SEARCH("Deputy",M13)))),"Position Allowance - Minister",IF(ISNUMBER(SEARCH("Deputy Director",M13)),"Position Allowance - Deputy Director",IF(AND(ISNUMBER(SEARCH("Director",M13)),NOT(ISNUMBER(SEARCH("Deputy",M13)))),"Position Allowance - Director",IF(ISNUMBER(SEARCH("Division Chief",M13)),"Position Allowance - Division Chief",IF(ISNUMBER(SEARCH("Section Chief",M13)),"Position Allowance - Section Chief","Position Allowance - General Staff")))))) -> Position Allowance - General Staff | AR13: =IFERROR(VLOOKUP(T13,LK_OrgMaster!$B$4:$G$89,6,FALSE()),"No") -> No | AS13: =IFERROR(VLOOKUP(T13,LK_OrgMaster!$B$4:$H$89,7,FALSE()),"None") -> None | AT13: 40218 | AV13: 40218 | AW13: 46023 | AX13: Initial Load | AY13: Record created during payroll system initial data load (Jan 2026).
A14: LAO00011 | B14: Dr. | C14: Vongphet | D14: Bounseng | E14: Male | F14: 31639 | G14: vongphet.bounseng@gov.la | H14: +856 20 94557602 | I14: 35026 | J14: =IFERROR(DATEDIF(I14,TODAY(),"Y"),0) -> 30 | K14: =IFERROR(DATE(YEAR(F14)+60,MONTH(F14),DAY(F14)),"") -> 53554 | L14: Permanent | M14: Officer | N14: Bachelor's Degree | O14: 0 | P14: =IFERROR(SUMPRODUCT((LK_GradeDerivation!$A$4:$A$135=N14)*(IF(O14="",0,O14)>=LK_GradeDerivation!$B$4:$B$135)*(IF(O14="",0,O14)<=LK_GradeDerivation!$C$4:$C$135)*LK_GradeDerivation!$D$4:$D$135),1) -> 4 | Q14: =IFERROR(SUMPRODUCT((LK_GradeDerivation!$A$4:$A$135=N14)*(IF(O14="",0,O14)>=LK_GradeDerivation!$B$4:$B$135)*(IF(O14="",0,O14)<=LK_GradeDerivation!$C$4:$C$135)*LK_GradeDerivation!$E$4:$E$135),1) -> 1 | R14: CSC000011 | S14: SSO6137284 | T14: Vientiane Capital Administration | U14: Department of Administration | V14: Records Division | W14: Lao PDR | X14: Vientiane Capital | Y14: Chanthabouli | Z14: =IFERROR(VLOOKUP(T14,LK_OrgMaster!$B$4:$H$89,5,FALSE()),"Administration") -> Administration | AA14: =IFERROR(VLOOKUP(X14,LK_LocationMaster!$D$4:$G$157,4,FALSE()),"No") -> No | AB14: =IF(W14="Foreign / International","Yes","No") -> No | AC14: =IFERROR(VLOOKUP(X14,LK_LocationMaster!$D$4:$H$157,5,FALSE()),"No") -> No | AD14: No. 485 | AE14: Street 36 | AF14: Baan Thongpone | AG14: Luang Prabang | AH14: 797100 | AI14: Lao PDR | AJ14: BCEL (Banque pour le Commerce Exterieur Lao) | AK14: BCEL Khammuane Branch | AL14: =IFERROR(INDEX(LK_BankMaster!$D$4:$D$23,MATCH(AJ14&"|"&AK14,LK_BankMaster!$H$4:$H$23,0)),"") | AM14: 337937327 | AN14: =IFERROR(VLOOKUP(AJ14,LK_BankMaster!$A$4:$E$23,5,FALSE()),"") | AO14: Yes | AP14: 1 | AQ14: =IF(ISNUMBER(SEARCH("Deputy Minister",M14)),"Position Allowance - Deputy Minister",IF(AND(ISNUMBER(SEARCH("Minister",M14)),NOT(ISNUMBER(SEARCH("Deputy",M14)))),"Position Allowance - Minister",IF(ISNUMBER(SEARCH("Deputy Director",M14)),"Position Allowance - Deputy Director",IF(AND(ISNUMBER(SEARCH("Director",M14)),NOT(ISNUMBER(SEARCH("Deputy",M14)))),"Position Allowance - Director",IF(ISNUMBER(SEARCH("Division Chief",M14)),"Position Allowance - Division Chief",IF(ISNUMBER(SEARCH("Section Chief",M14)),"Position Allowance - Section Chief","Position Allowance - General Staff")))))) -> Position Allowance - General Staff | AR14: =IFERROR(VLOOKUP(T14,LK_OrgMaster!$B$4:$G$89,6,FALSE()),"No") -> No | AS14: =IFERROR(VLOOKUP(T14,LK_OrgMaster!$B$4:$H$89,7,FALSE()),"None") -> None | AT14: 35026 | AV14: 35026 | AW14: 46023 | AX14: Initial Load | AY14: Record created during payroll system initial data load (Jan 2026).
A15: LAO00012 | B15: Mrs. | C15: Lattana | D15: Souksavanh | E15: Female | F15: 31932 | G15: lattana.souksava@gov.la | H15: +856 20 98626076 | I15: 43441 | J15: =IFERROR(DATEDIF(I15,TODAY(),"Y"),0) -> 7 | K15: =IFERROR(DATE(YEAR(F15)+60,MONTH(F15),DAY(F15)),"") -> 53847 | L15: Permanent | M15: Division Chief | N15: Master's Degree | O15: 6 | P15: =IFERROR(SUMPRODUCT((LK_GradeDerivation!$A$4:$A$135=N15)*(IF(O15="",0,O15)>=LK_GradeDerivation!$B$4:$B$135)*(IF(O15="",0,O15)<=LK_GradeDerivation!$C$4:$C$135)*LK_GradeDerivation!$D$4:$D$135),1) -> 5 | Q15: =IFERROR(SUMPRODUCT((LK_GradeDerivation!$A$4:$A$135=N15)*(IF(O15="",0,O15)>=LK_GradeDerivation!$B$4:$B$135)*(IF(O15="",0,O15)<=LK_GradeDerivation!$C$4:$C$135)*LK_GradeDerivation!$E$4:$E$135),1) -> 4 | R15: CSC000012 | S15: SSO5638893 | T15: Vientiane Capital Administration | U15: Department of Administration | V15: IT Division | W15: Lao PDR | X15: Vientiane Capital | Y15: Mayparkngum | Z15: =IFERROR(VLOOKUP(T15,LK_OrgMaster!$B$4:$H$89,5,FALSE()),"Administration") -> Administration | AA15: =IFERROR(VLOOKUP(X15,LK_LocationMaster!$D$4:$G$157,4,FALSE()),"No") -> No | AB15: =IF(W15="Foreign / International","Yes","No") -> No | AC15: =IFERROR(VLOOKUP(X15,LK_LocationMaster!$D$4:$H$157,5,FALSE()),"No") -> No | AD15: No. 103 | AE15: Samsenthai Road | AF15: Baan Naxaythong | AG15: Bokeo | AH15: 691200 | AI15: Lao PDR | AJ15: Lao Development Bank (LDB) | AK15: LDB Savannakhet Branch | AL15: =IFERROR(INDEX(LK_BankMaster!$D$4:$D$23,MATCH(AJ15&"|"&AK15,LK_BankMaster!$H$4:$H$23,0)),"") | AM15: 332341238 | AN15: =IFERROR(VLOOKUP(AJ15,LK_BankMaster!$A$4:$E$23,5,FALSE()),"") | AO15: No | AP15: 0 | AQ15: =IF(ISNUMBER(SEARCH("Deputy Minister",M15)),"Position Allowance - Deputy Minister",IF(AND(ISNUMBER(SEARCH("Minister",M15)),NOT(ISNUMBER(SEARCH("Deputy",M15)))),"Position Allowance - Minister",IF(ISNUMBER(SEARCH("Deputy Director",M15)),"Position Allowance - Deputy Director",IF(AND(ISNUMBER(SEARCH("Director",M15)),NOT(ISNUMBER(SEARCH("Deputy",M15)))),"Position Allowance - Director",IF(ISNUMBER(SEARCH("Division Chief",M15)),"Position Allowance - Division Chief",IF(ISNUMBER(SEARCH("Section Chief",M15)),"Position Allowance - Section Chief","Position Allowance - General Staff")))))) -> Position Allowance - Division Chief | AR15: =IFERROR(VLOOKUP(T15,LK_OrgMaster!$B$4:$G$89,6,FALSE()),"No") -> No | AS15: =IFERROR(VLOOKUP(T15,LK_OrgMaster!$B$4:$H$89,7,FALSE()),"None") -> None | AT15: 43441 | AV15: 43441 | AW15: 46023 | AX15: Initial Load | AY15: Record created during payroll system initial data load (Jan 2026).
... A503: LAO00500 | B503: Mrs. | C503: Vilayhong | D503: Luanglath | E503: Female | F503: 26615 | G503: vilayhong.luanglat@gov.la | H503: +856 20 64051322 | I503: 39991 | J503: =IFERROR(DATEDIF(I503,TODAY(),"Y"),0) -> 16 | K503: =IFERROR(DATE(YEAR(F503)+60,MONTH(F503),DAY(F503)),"") -> 48530 | L503: Permanent | M503: Administrative Officer | N503: Bachelor's Degree | O503: 14 | P503: =IFERROR(SUMPRODUCT((LK_GradeDerivation!$A$4:$A$135=N503)*(IF(O503="",0,O503)>=LK_GradeDerivation!$B$4:$B$135)*(IF(O503="",0,O503)<=LK_GradeDerivation!$C$4:$C$135)*LK_GradeDerivation!$D$4:$D$135),1) -> 4 | Q503: =IFERROR(SUMPRODUCT((LK_GradeDerivation!$A$4:$A$135=N503)*(IF(O503="",0,O503)>=LK_GradeDerivation!$B$4:$B$135)*(IF(O503="",0,O503)<=LK_GradeDerivation!$C$4:$C$135)*LK_GradeDerivation!$E$4:$E$135),1) -> 8 | R503: CSC000500 | S503: SSO3694288 | T503: Ministry of Industry & Commerce (MoIC) | U503: Department of Domestic Trade | V503: Market Regulation Division | W503: Lao PDR | X503: Sayabouli | Y503: Xienghon | Z503: =IFERROR(VLOOKUP(T503,LK_OrgMaster!$B$4:$H$89,5,FALSE()),"Administration") -> Administration | AA503: =IFERROR(VLOOKUP(X503,LK_LocationMaster!$D$4:$G$157,4,FALSE()),"No") -> Yes | AB503: =IF(W503="Foreign / International","Yes","No") -> No | AC503: =IFERROR(VLOOKUP(X503,LK_LocationMaster!$D$4:$H$157,5,FALSE()),"No") -> No | AD503: No. 759 | AE503: Samsenthai Road | AF503: Baan Dongpalane | AG503: Luang Prabang | AH503: 918900 | AI503: Lao PDR | AJ503: Joint Development Bank (JDB) | AK503: JDB Vientiane Branch | AL503: =IFERROR(INDEX(LK_BankMaster!$D$4:$D$23,MATCH(AJ503&"|"&AK503,LK_BankMaster!$H$4:$H$23,0)),"") | AM503: 448442536 | AN503: =IFERROR(VLOOKUP(AJ503,LK_BankMaster!$A$4:$E$23,5,FALSE()),"") | AO503: Yes | AP503: 2 | AQ503: =IF(ISNUMBER(SEARCH("Deputy Minister",M503)),"Position Allowance - Deputy Minister",IF(AND(ISNUMBER(SEARCH("Minister",M503)),NOT(ISNUMBER(SEARCH("Deputy",M503)))),"Position Allowance - Minister",IF(ISNUMBER(SEARCH("Deputy Director",M503)),"Position Allowance - Deputy Director",IF(AND(ISNUMBER(SEARCH("Director",M503)),NOT(ISNUMBER(SEARCH("Deputy",M503)))),"Position Allowance - Director",IF(ISNUMBER(SEARCH("Division Chief",M503)),"Position Allowance - Division Chief",IF(ISNUMBER(SEARCH("Section Chief",M503)),"Position Allowance - Section Chief","Position Allowance - General Staff")))))) -> Position Allowance - General Staff | AR503: =IFERROR(VLOOKUP(T503,LK_OrgMaster!$B$4:$G$89,6,FALSE()),"No") -> No | AS503: =IFERROR(VLOOKUP(T503,LK_OrgMaster!$B$4:$H$89,7,FALSE()),"None") -> None | AT503: 39991 | AV503: 39991 | AW503: 46023 | AX503: Initial Load | AY503: Record created during payroll system initial data load (Jan 2026).

Sheet PAYROLL_CALC
A1: MONTHLY PAYROLL CALCULATION — Lao PDR Government | All amounts in LAK | Yellow = free input | Green = formula | Cols Y-AA = Other Allowances (free) | Cols AG-AH = Additional Deductions (free)
A2: Payroll Month → | B2: UPDATE MONTH HERE | E2: EMPLOYEE IDENTITY | F2: SALARY BASE | M2: ⬆ EARNINGS / ALLOWANCES | Y2: 🔓 OTHER ALLOWANCES | AB2: TOTAL ALLOW | AC2: GROSS | AG2: 🔓 OTHER DEDUCTIONS | AI2: TOTAL DED | AJ2: NET SALARY
A3: Emp Code | B3: First Name | C3: Last Name | D3: Ministry / Org | E3: Position | F3: Profession | G3: Grade | H3: Step | I3: Grade-Step Key | J3: Multiplier | K3: Index Value (LAK) | L3: Basic Salary (LAK) | M3: Position Allowance | N3: Yrs Service Allowance | O3: Teaching Allowance | P3: Medical Allowance | Q3: NA Member Allowance | R3: Hardship/ Hazardous | S3: Remote Area Allowance | T3: Foreign Living Allowance | U3: Fuel Benefit (Gr≥8) | V3: Spouse Benefit | W3: Child Benefit | X3: Other Subsidies | Y3: Other Allowance 1 (Description + Amount) | Z3: Other Allowance 2 (Description + Amount) | AA3: Other Allowance 3 (Description + Amount) | AB3: Total Allowances (LAK) | AC3: GROSS EARNINGS (LAK) | AD3: SSO Employee Contrib. | AE3: Taxable Income | AF3: PIT Amount (LAK) | AG3: Additional Deduction 1 (e.g. Loan Repayment) | AH3: Additional Deduction 2 (e.g. Advance Recovery) | AI3: TOTAL DEDUCTIONS (LAK) | AJ3: NET SALARY (LAK)
A4: =EMPLOYEE_MASTER!A4 -> LAO00001 | B4: =EMPLOYEE_MASTER!C4 -> Khamsone | C4: =EMPLOYEE_MASTER!D4 -> Bounseng | D4: =EMPLOYEE_MASTER!T4 -> Ministry of Education and Sports (MoES) | E4: =EMPLOYEE_MASTER!M4 -> School Principal | F4: =EMPLOYEE_MASTER!Z4 -> Teacher | G4: =EMPLOYEE_MASTER!P4 -> 4 | H4: =EMPLOYEE_MASTER!Q4 -> 13 | I4: ="G"&TEXT(G4,"00")&"-S"&TEXT(H4,"00") -> G04-S13 | J4: =IFERROR(VLOOKUP(I4,LK_GradeStep!$C$4:$D$85,2,0),0) -> 328 | K4: =IFERROR(VLOOKUP(I4,LK_GradeStep!$C$4:$E$85,3,0),10000) -> 10000 | L4: =IFERROR(J4*K4,0) -> 3280000 | M4: =IFERROR(VLOOKUP(EMPLOYEE_MASTER!AQ4,LK_AllowanceRates!$A$5:$B$11,2,0),0) -> 900000 | N4: =IFERROR(IF(EMPLOYEE_MASTER!J4<=5, EMPLOYEE_MASTER!J4*LK_AllowanceRates!$B$12,IF(EMPLOYEE_MASTER!J4<=15, EMPLOYEE_MASTER!J4*LK_AllowanceRates!$B$13,IF(EMPLOYEE_MASTER!J4<=25, EMPLOYEE_MASTER!J4*LK_AllowanceRates!$B$14,EMPLOYEE_MASTER!J4*LK_AllowanceRates!$B$15))),0) -> 140000 | O4: =IF(EMPLOYEE_MASTER!AS4="Teaching",L4*LK_AllowanceRates!$B$16,0) -> 656000 | P4: =IF(EMPLOYEE_MASTER!AS4="Medical",LK_AllowanceRates!$B$17,0) -> 0 | Q4: =IF(EMPLOYEE_MASTER!AR4="Yes",LK_AllowanceRates!$B$18,0) -> 0 | R4: =IF(EMPLOYEE_MASTER!AC4="Yes",LK_AllowanceRates!$B$19,0) -> 1000000 | S4: =IF(EMPLOYEE_MASTER!AA4="Yes",L4*LK_AllowanceRates!$B$20,0) -> 820000 | T4: =IF(EMPLOYEE_MASTER!AB4="Yes",LK_AllowanceRates!$B$21,0) -> 0 | U4: =IF(EMPLOYEE_MASTER!P4>=6,LK_AllowanceRates!$B$22,0) -> 0 | V4: =IF(EMPLOYEE_MASTER!AO4="Yes",LK_AllowanceRates!$B$23,0) -> 200000 | W4: =EMPLOYEE_MASTER!AP4*LK_AllowanceRates!$B$24 -> 400000 | X4: 0 | Y4: 0 | Z4: 0 | AA4: 0 | AB4: =SUM(M4:AA4) -> 4116000 | AC4: =L4+AB4 -> 7396000 | AD4: =ROUND(L4*LK_AllowanceRates!$B$25/100,0) -> 180400 | AE4: =IFERROR(AC4-AD4,0) -> 7215600 | AF4: =IFERROR(IF(AE4<=1300000,0,IF(AE4<=5000000,(AE4-1300000)*0.05,IF(AE4<=10000000,185000+(AE4-5000000)*0.1,IF(AE4<=20000000,685000+(AE4-10000000)*0.15,IF(AE4<=40000000,2185000+(AE4-20000000)*0.2,6185000+(AE4-40000000)*0.24))))),0) -> 406560 | AG4: 0 | AH4: 0 | AI4: =AD4+AF4+AG4+AH4 -> 586960 | AJ4: =IFERROR(AC4-AI4,0) -> 6809040
